<?xml version="1.0"?>
<robot name="biped">

  <!-- ================= BASE ================= -->
  <link name="pelvis">
    <inertial>
      <origin xyz="0 0 0"/>
      <mass value="10"/>
      <inertia ixx="0.1" iyy="0.1" izz="0.1"
               ixy="0" ixz="0" iyz="0"/>
    </inertial>
    <visual>
      <geometry>
        <box size="0.3 0.2 0.15"/>
      </geometry>
    </visual>
    <collision>
      <geometry>
        <box size="0.3 0.2 0.15"/>
      </geometry>
    </collision>
  </link>

  <!-- ================= LEFT LEG ================= -->
  <link name="left_thigh">
    <inertial>
      <mass value="3"/>
      <inertia ixx="0.05" iyy="0.05" izz="0.01"
               ixy="0" ixz="0" iyz="0"/>
    </inertial>
    <visual>
      <geometry>
        <cylinder radius="0.05" length="0.4"/>
      </geometry>
    </visual>
    <collision>
      <geometry>
        <cylinder radius="0.05" length="0.4"/>
      </geometry>
    </collision>
  </link>

  <joint name="left_hip" type="revolute">
    <parent link="pelvis"/>
    <child link="left_thigh"/>
    <origin xyz="0 0.15 -0.075"/>
    <axis xyz="1 0 0"/>
    <limit lower="-1.0" upper="1.0" effort="50" velocity="1.0"/>
    <dynamics damping="10.0" friction="1.0"/>
  </joint>

  <link name="left_shin">
    <inertial>
      <mass value="2"/>
      <inertia ixx="0.04" iyy="0.04" izz="0.01"
               ixy="0" ixz="0" iyz="0"/>
    </inertial>
    <visual>
      <geometry>
        <cylinder radius="0.04" length="0.4"/>
      </geometry>
    </visual>
    <collision>
      <geometry>
        <cylinder radius="0.04" length="0.4"/>
      </geometry>
    </collision>
  </link>

  <joint name="left_knee" type="revolute">
    <parent link="left_thigh"/>
    <child link="left_shin"/>
    <origin xyz="0 0 -0.4"/>
    <axis xyz="1 0 0"/>
    <limit lower="0" upper="1.5" effort="50" velocity="1.0"/>
    <dynamics damping="10.0" friction="1.0"/>
  </joint>

  <link name="left_foot">
    <inertial>
      <mass value="1"/>
      <inertia ixx="0.01" iyy="0.01" izz="0.01"
               ixy="0" ixz="0" iyz="0"/>
    </inertial>
    <visual>
      <geometry>
        <box size="0.2 0.1 0.05"/>
      </geometry>
    </visual>
    <collision>
      <geometry>
        <box size="0.2 0.1 0.05"/>
      </geometry>
    </collision>
  </link>

  <joint name="left_ankle" type="revolute">
    <parent link="left_shin"/>
    <child link="left_foot"/>
    <origin xyz="0 0 -0.4"/>
    <axis xyz="1 0 0"/>
    <limit lower="-0.5" upper="0.5" effort="20" velocity="1.0"/>
    <dynamics damping="10.0" friction="1.0"/>
  </joint>

<gazebo>
  <sensor name="left_foot_contact_sensor" type="contact">
    <pose frame="left_foot">0 0 0 0 0 0</pose>
    <contact>
      <collision>left_foot</collision>
      <surface>
        <friction>
          <ode>
            <mu>1.0</mu>
            <mu2>1.0</mu2>
          </ode>
        </friction>
      </surface>
    </contact>
  </sensor>
</gazebo>


  <!-- ================= RIGHT LEG ================= -->
  <link name="right_thigh">
    <inertial>
      <mass value="3"/>
      <inertia ixx="0.05" iyy="0.05" izz="0.01"
               ixy="0" ixz="0" iyz="0"/>
    </inertial>
    <visual>
      <geometry>
        <cylinder radius="0.05" length="0.4"/>
      </geometry>
    </visual>
    <collision>
      <geometry>
        <cylinder radius="0.05" length="0.4"/>
      </geometry>
    </collision>
  </link>

  <joint name="right_hip" type="revolute">
    <parent link="pelvis"/>
    <child link="right_thigh"/>
    <origin xyz="0 -0.15 -0.075"/>
    <axis xyz="1 0 0"/>
    <limit lower="-1.0" upper="1.0" effort="50" velocity="1.0"/>
    <dynamics damping="10.0" friction="1.0"/>
  </joint>

  <link name="right_shin">
    <inertial>
      <mass value="2"/>
      <inertia ixx="0.04" iyy="0.04" izz="0.01"
               ixy="0" ixz="0" iyz="0"/>
    </inertial>
    <visual>
      <geometry>
        <cylinder radius="0.04" length="0.4"/>
      </geometry>
    </visual>
    <collision>
      <geometry>
        <cylinder radius="0.04" length="0.4"/>
      </geometry>
    </collision>
  </link>

  <joint name="right_knee" type="revolute">
    <parent link="right_thigh"/>
    <child link="right_shin"/>
    <origin xyz="0 0 -0.4"/>
    <axis xyz="1 0 0"/>
    <limit lower="0" upper="1.5" effort="50" velocity="1.0"/>
    <dynamics damping="10.0" friction="1.0"/>
  </joint>

  <link name="right_foot">
    <inertial>
      <mass value="1"/>
      <inertia ixx="0.01" iyy="0.01" izz="0.01"
               ixy="0" ixz="0" iyz="0"/>
    </inertial>
    <visual>
      <geometry>
        <box size="0.2 0.1 0.05"/>
      </geometry>
    </visual>
    <collision>
      <geometry>
        <box size="0.2 0.1 0.05"/>
      </geometry>
    </collision>
  </link>

  <joint name="right_ankle" type="revolute">
    <parent link="right_shin"/>
    <child link="right_foot"/>
    <origin xyz="0 0 -0.4"/>
    <axis xyz="1 0 0"/>
    <limit lower="-0.5" upper="0.5" effort="20" velocity="1.0"/>
    <dynamics damping="10.0" friction="1.0"/>
  </joint>

<gazebo>
  <sensor name="right_foot_contact_sensor" type="contact">
    <pose frame="right_foot">0 0 0 0 0 0</pose>
    <contact>
      <collision>right_foot</collision>
      <surface>
        <friction>
          <ode>
            <mu>1.0</mu>
            <mu2>1.0</mu2>
          </ode>
        </friction>
      </surface>
    </contact>
  </sensor>
</gazebo>


<!-- ================= TRANSMISSIONS ================= -->

<transmission name="left_hip_trans">
  <type>transmission_interface/SimpleTransmission</type>
  <joint name="left_hip">
    <hardwareInterface>hardware_interface/EffortJointInterface</hardwareInterface>
  </joint>
  <actuator name="left_hip_motor">
    <mechanicalReduction>1</mechanicalReduction>
  </actuator>
</transmission>

<transmission name="left_knee_trans">
  <type>transmission_interface/SimpleTransmission</type>
  <joint name="left_knee">
    <hardwareInterface>hardware_interface/EffortJointInterface</hardwareInterface>
  </joint>
  <actuator name="left_knee_motor">
    <mechanicalReduction>1</mechanicalReduction>
  </actuator>
</transmission>

<transmission name="left_ankle_trans">
  <type>transmission_interface/SimpleTransmission</type>
  <joint name="left_ankle">
    <hardwareInterface>hardware_interface/EffortJointInterface</hardwareInterface>
  </joint>
  <actuator name="left_ankle_motor">
    <mechanicalReduction>1</mechanicalReduction>
  </actuator>
</transmission>

<transmission name="right_hip_trans">
  <type>transmission_interface/SimpleTransmission</type>
  <joint name="right_hip">
    <hardwareInterface>hardware_interface/EffortJointInterface</hardwareInterface>
  </joint>
  <actuator name="right_hip_motor">
    <mechanicalReduction>1</mechanicalReduction>
  </actuator>
</transmission>

<transmission name="right_knee_trans">
  <type>transmission_interface/SimpleTransmission</type>
  <joint name="right_knee">
    <hardwareInterface>hardware_interface/EffortJointInterface</hardwareInterface>
  </joint>
  <actuator name="right_knee_motor">
    <mechanicalReduction>1</mechanicalReduction>
  </actuator>
</transmission>

<transmission name="right_ankle_trans">
  <type>transmission_interface/SimpleTransmission</type>
  <joint name="right_ankle">
    <hardwareInterface>hardware_interface/EffortJointInterface</hardwareInterface>
  </joint>
  <actuator name="right_ankle_motor">
    <mechanicalReduction>1</mechanicalReduction>
  </actuator>
</transmission>

<!-- ================= GAZEBO ROS CONTROL ================= -->
<gazebo>
  <plugin filename="libgazebo_ros_control.so" name="gazebo_ros_control">
    <robotNamespace>/biped</robotNamespace>
  </plugin>
</gazebo>

<gazebo>
  <self_collide>false</self_collide>
</gazebo>


</robot>
